2021-11-19 16:46:47,908 INFO: Shredhub startup [in /Users/taylorvaroglu/Desktop/DesktopFiles/mod4/practice/shredhub/app/__init__.py:32]
2021-11-19 16:47:04,357 ERROR: Exception on /edit_profile [POST] [in /Users/taylorvaroglu/Desktop/DesktopFiles/mod4/practice/shredhub/venv/lib/python3.9/site-packages/flask/app.py:1457]
Traceback (most recent call last):
  File "/Users/taylorvaroglu/Desktop/DesktopFiles/mod4/practice/shredhub/venv/lib/python3.9/site-packages/sqlalchemy/engine/base.py", line 1802, in _execute_context
    self.dialect.do_execute(
  File "/Users/taylorvaroglu/Desktop/DesktopFiles/mod4/practice/shredhub/venv/lib/python3.9/site-packages/sqlalchemy/engine/default.py", line 719, in do_execute
    cursor.execute(statement, parameters)
psycopg2.errors.UniqueViolation: duplicate key value violates unique constraint "ix_user_username"
DETAIL:  Key (username)=(Admin) already exists.


The above exception was the direct cause of the following exception:

Traceback (most recent call last):
  File "/Users/taylorvaroglu/Desktop/DesktopFiles/mod4/practice/shredhub/venv/lib/python3.9/site-packages/flask/app.py", line 2073, in wsgi_app
    response = self.full_dispatch_request()
  File "/Users/taylorvaroglu/Desktop/DesktopFiles/mod4/practice/shredhub/venv/lib/python3.9/site-packages/flask/app.py", line 1518, in full_dispatch_request
    rv = self.handle_user_exception(e)
  File "/Users/taylorvaroglu/Desktop/DesktopFiles/mod4/practice/shredhub/venv/lib/python3.9/site-packages/flask/app.py", line 1516, in full_dispatch_request
    rv = self.dispatch_request()
  File "/Users/taylorvaroglu/Desktop/DesktopFiles/mod4/practice/shredhub/venv/lib/python3.9/site-packages/flask/app.py", line 1502, in dispatch_request
    return self.ensure_sync(self.view_functions[rule.endpoint])(**req.view_args)
  File "/Users/taylorvaroglu/Desktop/DesktopFiles/mod4/practice/shredhub/venv/lib/python3.9/site-packages/flask_login/utils.py", line 272, in decorated_view
    return func(*args, **kwargs)
  File "/Users/taylorvaroglu/Desktop/DesktopFiles/mod4/practice/shredhub/app/routes.py", line 37, in edit_profile
    db.session.commit()
  File "<string>", line 2, in commit
  File "/Users/taylorvaroglu/Desktop/DesktopFiles/mod4/practice/shredhub/venv/lib/python3.9/site-packages/sqlalchemy/orm/session.py", line 1428, in commit
    self._transaction.commit(_to_root=self.future)
  File "/Users/taylorvaroglu/Desktop/DesktopFiles/mod4/practice/shredhub/venv/lib/python3.9/site-packages/sqlalchemy/orm/session.py", line 829, in commit
    self._prepare_impl()
  File "/Users/taylorvaroglu/Desktop/DesktopFiles/mod4/practice/shredhub/venv/lib/python3.9/site-packages/sqlalchemy/orm/session.py", line 808, in _prepare_impl
    self.session.flush()
  File "/Users/taylorvaroglu/Desktop/DesktopFiles/mod4/practice/shredhub/venv/lib/python3.9/site-packages/sqlalchemy/orm/session.py", line 3345, in flush
    self._flush(objects)
  File "/Users/taylorvaroglu/Desktop/DesktopFiles/mod4/practice/shredhub/venv/lib/python3.9/site-packages/sqlalchemy/orm/session.py", line 3485, in _flush
    transaction.rollback(_capture_exception=True)
  File "/Users/taylorvaroglu/Desktop/DesktopFiles/mod4/practice/shredhub/venv/lib/python3.9/site-packages/sqlalchemy/util/langhelpers.py", line 70, in __exit__
    compat.raise_(
  File "/Users/taylorvaroglu/Desktop/DesktopFiles/mod4/practice/shredhub/venv/lib/python3.9/site-packages/sqlalchemy/util/compat.py", line 207, in raise_
    raise exception
  File "/Users/taylorvaroglu/Desktop/DesktopFiles/mod4/practice/shredhub/venv/lib/python3.9/site-packages/sqlalchemy/orm/session.py", line 3445, in _flush
    flush_context.execute()
  File "/Users/taylorvaroglu/Desktop/DesktopFiles/mod4/practice/shredhub/venv/lib/python3.9/site-packages/sqlalchemy/orm/unitofwork.py", line 456, in execute
    rec.execute(self)
  File "/Users/taylorvaroglu/Desktop/DesktopFiles/mod4/practice/shredhub/venv/lib/python3.9/site-packages/sqlalchemy/orm/unitofwork.py", line 630, in execute
    util.preloaded.orm_persistence.save_obj(
  File "/Users/taylorvaroglu/Desktop/DesktopFiles/mod4/practice/shredhub/venv/lib/python3.9/site-packages/sqlalchemy/orm/persistence.py", line 236, in save_obj
    _emit_update_statements(
  File "/Users/taylorvaroglu/Desktop/DesktopFiles/mod4/practice/shredhub/venv/lib/python3.9/site-packages/sqlalchemy/orm/persistence.py", line 1000, in _emit_update_statements
    c = connection._execute_20(
  File "/Users/taylorvaroglu/Desktop/DesktopFiles/mod4/practice/shredhub/venv/lib/python3.9/site-packages/sqlalchemy/engine/base.py", line 1614, in _execute_20
    return meth(self, args_10style, kwargs_10style, execution_options)
  File "/Users/taylorvaroglu/Desktop/DesktopFiles/mod4/practice/shredhub/venv/lib/python3.9/site-packages/sqlalchemy/sql/elements.py", line 325, in _execute_on_connection
    return connection._execute_clauseelement(
  File "/Users/taylorvaroglu/Desktop/DesktopFiles/mod4/practice/shredhub/venv/lib/python3.9/site-packages/sqlalchemy/engine/base.py", line 1481, in _execute_clauseelement
    ret = self._execute_context(
  File "/Users/taylorvaroglu/Desktop/DesktopFiles/mod4/practice/shredhub/venv/lib/python3.9/site-packages/sqlalchemy/engine/base.py", line 1845, in _execute_context
    self._handle_dbapi_exception(
  File "/Users/taylorvaroglu/Desktop/DesktopFiles/mod4/practice/shredhub/venv/lib/python3.9/site-packages/sqlalchemy/engine/base.py", line 2026, in _handle_dbapi_exception
    util.raise_(
  File "/Users/taylorvaroglu/Desktop/DesktopFiles/mod4/practice/shredhub/venv/lib/python3.9/site-packages/sqlalchemy/util/compat.py", line 207, in raise_
    raise exception
  File "/Users/taylorvaroglu/Desktop/DesktopFiles/mod4/practice/shredhub/venv/lib/python3.9/site-packages/sqlalchemy/engine/base.py", line 1802, in _execute_context
    self.dialect.do_execute(
  File "/Users/taylorvaroglu/Desktop/DesktopFiles/mod4/practice/shredhub/venv/lib/python3.9/site-packages/sqlalchemy/engine/default.py", line 719, in do_execute
    cursor.execute(statement, parameters)
sqlalchemy.exc.IntegrityError: (psycopg2.errors.UniqueViolation) duplicate key value violates unique constraint "ix_user_username"
DETAIL:  Key (username)=(Admin) already exists.

[SQL: UPDATE "user" SET username=%(username)s, about_me=%(about_me)s, updated_at=%(updated_at)s WHERE "user".id = %(user_id)s]
[parameters: {'username': 'Admin', 'about_me': 'Yo yo!!', 'updated_at': datetime.datetime(2021, 11, 19, 23, 47, 4, 334450), 'user_id': 22}]
(Background on this error at: https://sqlalche.me/e/14/gkpj)
